<mujoco model="CableAddin">
  <include file="scene.xml"/>
  <extension>
    <plugin plugin="mujoco.elasticity.cable"/>
  </extension>
  
  <statistic center="0 0 0" extent="1"/>
  <visual>
    <global elevation="-30"/>
  </visual>

  <size memory="2M"/>

  <worldbody>
    <!-- Parent: Box 1 -->
    <body name="box1" pos="-.15 0 0.1">
      <geom type="box" size="0.1 0.1 0.1" mass="1.0" rgba="0 0 1 1"/>
      <joint name="box1_slide" type="slide" axis="1 0 0" damping="0.01"/>
      
      <!-- Child: Rope -->
      <body name="rope" pos="0 0 0">
        <composite type="cable" curve="s" count="51 1 1" size="1" offset="0 0 0" initial="none">
          <plugin plugin="mujoco.elasticity.cable">
            <!-- Elasticity properties -->
            <config key="twist" value="1e7"/>
            <config key="bend" value="4e6"/>
            <config key="vmax" value="0.05"/>
          </plugin>
          <joint kind="main" damping=".015"/>
          <geom type="capsule" size=".005" rgba=".8 .2 .1 1" condim="1"/>
        </composite>
      </body>
    </body>
    <!-- Grandchild: Box 2 -->
    <body name="box2" pos=".8 0 0.1">
        <geom type="box" size="0.1 0.1 0.1" mass=".5" rgba="1 0 0 1"/>
        <site name="box2_site" pos="0 0 0"/>
        <joint type="free"/>
    </body>
  </worldbody>

  <!-- Contact handling -->
  <equality>
    <!-- Weld constraint between the last segment (B_last) and box2 -->
    <connect name="rope_to_box2" body1="B_last" body2="box2" anchor="0 0 0"/>
  </equality>
  <contact>
    <exclude body1="rope" body2="box1"/>
    <exclude body1="rope" body2="box2"/>
  </contact>

  <!-- Actuator to control Box 1 -->
  <actuator>
    <motor joint="box1_slide" gear="1" ctrlrange="-1 1"/>
  </actuator>
</mujoco>
